Workbook

Sheet Calc Fixtures v2
A1: TestCase | B1: Cash | C1: Burn | D1: MRR | E1: Revenue | F1: COGS | G1: OpEx | H1: Prev | I1: Curr | J1: StartMRR | K1: Expansion | L1: Contraction | M1: Churn | N1: ARPA | O1: GM | P1: ChurnRate | Q1: Spend | R1: NewCustomers | S1: Notes | T1: Expected_ARR | U1: Expected_GM | V1: Expected_Burn | W1: Expected_Runway | X1: Expected_MoMGrowth | Y1: Expected_NRR | Z1: Expected_CAC | AA1: Expected_LTV | AB1: Expected_Payback | AC1: App_ARR | AD1: App_GM | AE1: App_Burn | AF1: App_Runway | AG1: App_MoMGrowth | AH1: App_NRR | AI1: App_CAC | AJ1: App_LTV | AK1: App_Payback | AL1: Calc_ARR | AM1: Calc_GM | AN1: Calc_Burn | AO1: Calc_Runway | AP1: Calc_MoMGrowth | AQ1: Calc_NRR | AR1: Calc_CAC | AS1: Calc_LTV | AT1: Calc_Payback | AU1: PF_ARR | AV1: PF_GM | AW1: PF_Burn | AX1: PF_Runway | AY1: PF_MoM | AZ1: PF_NRR | BA1: PF_CAC | BB1: PF_LTV | BC1: PF_Payback
A2: TC01_RUNWAY_BASIC | B2: 4500000 | C2: 382000 | S2: Runway = Cash/Burn; expect ~11.78 (display 11.8) | W2: 11.780105 | AL2: =IF([@MRR]="", "", [@MRR]*12) | AM2: =IF(OR([@Revenue]="",[@Revenue]<=0), "", ([@Revenue]-[@COGS]) / [@Revenue]) | AN2: =IF(OR([@Revenue]="",[@OpEx]="",[@COGS]=""), "", MAX(0, [@OpEx]+[@COGS]-[@Revenue])) | AO2: =IF([@Cash]="", "", IF(OR([@Burn]="",[@Burn]=0), IF([@Calc_Burn]="", "", IF([@Calc_Burn]<=0, "Cashflow+", [@Cash]/[@Calc_Burn])), IF([@Burn]<=0, "Cashflow+", [@Cash]/[@Burn]))) | AP2: =IF(OR([@Prev]="",[@Curr]=""), "", IF([@Prev]<1000, "N/A", ([@Curr]-[@Prev]) / [@Prev])) | AQ2: =IF([@StartMRR]="", "", IF([@StartMRR]<1000, "N/A", ([@StartMRR]+[@Expansion]-[@Contraction]-[@Churn]) / [@StartMRR])) | AR2: =IF(OR([@Spend]="",[@NewCustomers]=""), "", IF([@NewCustomers]<=0, "N/A", [@Spend]/[@NewCustomers])) | AS2: =IF(OR([@ARPA]="",[@GM]="",[@ChurnRate]=""), "", IF([@ChurnRate]<=0, "N/A", [@ARPA]*[@GM]/[@ChurnRate])) | AT2: =IF(OR([@ARPA]="",[@GM]=""), "", IF(([@ARPA]*[@GM])<=0, "N/A", 200/([@ARPA]*[@GM]))) | AU2: =IF([@App_ARR]="","",IF(ABS([@App_ARR]-[@Calc_ARR])<0.01,"PASS","FAIL")) | AV2: =IF([@App_GM]="","",IF(ABS([@App_GM]-[@Calc_GM])<0.0001,"PASS","FAIL")) | AW2: =IF([@App_Burn]="","",IF(ABS([@App_Burn]-[@Calc_Burn])<1,"PASS","FAIL")) | AX2: =IF([@App_Runway]="","",IF(OR(AND([@App_Runway]="Cashflow+",[@Calc_Runway]="Cashflow+"),ABS([@App_Runway]-[@Calc_Runway])<0.01),"PASS","FAIL")) | AY2: =IF([@App_MoMGrowth]="","",IF(OR(AND([@App_MoMGrowth]="N/A",[@Calc_MoMGrowth]="N/A"),ABS([@App_MoMGrowth]-[@Calc_MoMGrowth])<0.0001),"PASS","FAIL")) | AZ2: =IF([@App_NRR]="","",IF(OR(AND([@App_NRR]="N/A",[@Calc_NRR]="N/A"),ABS([@App_NRR]-[@Calc_NRR])<0.0001),"PASS","FAIL")) | BA2: =IF([@App_CAC]="","",IF(OR(AND([@App_CAC]="N/A",[@Calc_CAC]="N/A"),ABS([@App_CAC]-[@Calc_CAC])<0.01),"PASS","FAIL")) | BB2: =IF([@App_LTV]="","",IF(OR(AND([@App_LTV]="N/A",[@Calc_LTV]="N/A"),ABS([@App_LTV]-[@Calc_LTV])<0.01),"PASS","FAIL")) | BC2: =IF([@App_Payback]="","",IF(OR(AND([@App_Payback]="N/A",[@Calc_Payback]="N/A"),ABS([@App_Payback]-[@Calc_Payback])<0.01),"PASS","FAIL"))
A3: TC02_RUNWAY_BURN_ZERO | B3: 2000000 | C3: 0 | S3: Burn<=0 => Cashflow+ (guard) | W3: Cashflow+ | AL3: =IF([@MRR]="", "", [@MRR]*12) | AM3: =IF(OR([@Revenue]="",[@Revenue]<=0), "", ([@Revenue]-[@COGS]) / [@Revenue]) | AN3: =IF(OR([@Revenue]="",[@OpEx]="",[@COGS]=""), "", MAX(0, [@OpEx]+[@COGS]-[@Revenue])) | AO3: =IF([@Cash]="", "", IF(OR([@Burn]="",[@Burn]=0), IF([@Calc_Burn]="", "", IF([@Calc_Burn]<=0, "Cashflow+", [@Cash]/[@Calc_Burn])), IF([@Burn]<=0, "Cashflow+", [@Cash]/[@Burn]))) | AP3: =IF(OR([@Prev]="",[@Curr]=""), "", IF([@Prev]<1000, "N/A", ([@Curr]-[@Prev]) / [@Prev])) | AQ3: =IF([@StartMRR]="", "", IF([@StartMRR]<1000, "N/A", ([@StartMRR]+[@Expansion]-[@Contraction]-[@Churn]) / [@StartMRR])) | AR3: =IF(OR([@Spend]="",[@NewCustomers]=""), "", IF([@NewCustomers]<=0, "N/A", [@Spend]/[@NewCustomers])) | AS3: =IF(OR([@ARPA]="",[@GM]="",[@ChurnRate]=""), "", IF([@ChurnRate]<=0, "N/A", [@ARPA]*[@GM]/[@ChurnRate])) | AT3: =IF(OR([@ARPA]="",[@GM]=""), "", IF(([@ARPA]*[@GM])<=0, "N/A", 200/([@ARPA]*[@GM]))) | AU3: =IF([@App_ARR]="","",IF(ABS([@App_ARR]-[@Calc_ARR])<0.01,"PASS","FAIL")) | AV3: =IF([@App_GM]="","",IF(ABS([@App_GM]-[@Calc_GM])<0.0001,"PASS","FAIL")) | AW3: =IF([@App_Burn]="","",IF(ABS([@App_Burn]-[@Calc_Burn])<1,"PASS","FAIL")) | AX3: =IF([@App_Runway]="","",IF(OR(AND([@App_Runway]="Cashflow+",[@Calc_Runway]="Cashflow+"),ABS([@App_Runway]-[@Calc_Runway])<0.01),"PASS","FAIL")) | AY3: =IF([@App_MoMGrowth]="","",IF(OR(AND([@App_MoMGrowth]="N/A",[@Calc_MoMGrowth]="N/A"),ABS([@App_MoMGrowth]-[@Calc_MoMGrowth])<0.0001),"PASS","FAIL")) | AZ3: =IF([@App_NRR]="","",IF(OR(AND([@App_NRR]="N/A",[@Calc_NRR]="N/A"),ABS([@App_NRR]-[@Calc_NRR])<0.0001),"PASS","FAIL")) | BA3: =IF([@App_CAC]="","",IF(OR(AND([@App_CAC]="N/A",[@Calc_CAC]="N/A"),ABS([@App_CAC]-[@Calc_CAC])<0.01),"PASS","FAIL")) | BB3: =IF([@App_LTV]="","",IF(OR(AND([@App_LTV]="N/A",[@Calc_LTV]="N/A"),ABS([@App_LTV]-[@Calc_LTV])<0.01),"PASS","FAIL")) | BC3: =IF([@App_Payback]="","",IF(OR(AND([@App_Payback]="N/A",[@Calc_Payback]="N/A"),ABS([@App_Payback]-[@Calc_Payback])<0.01),"PASS","FAIL"))
A4: TC03_RUNWAY_NEGATIVE_BURN | B4: 2000000 | C4: -10000 | S4: Negative burn => Cashflow+ (guard) | W4: Cashflow+ | AL4: =IF([@MRR]="", "", [@MRR]*12) | AM4: =IF(OR([@Revenue]="",[@Revenue]<=0), "", ([@Revenue]-[@COGS]) / [@Revenue]) | AN4: =IF(OR([@Revenue]="",[@OpEx]="",[@COGS]=""), "", MAX(0, [@OpEx]+[@COGS]-[@Revenue])) | AO4: =IF([@Cash]="", "", IF(OR([@Burn]="",[@Burn]=0), IF([@Calc_Burn]="", "", IF([@Calc_Burn]<=0, "Cashflow+", [@Cash]/[@Calc_Burn])), IF([@Burn]<=0, "Cashflow+", [@Cash]/[@Burn]))) | AP4: =IF(OR([@Prev]="",[@Curr]=""), "", IF([@Prev]<1000, "N/A", ([@Curr]-[@Prev]) / [@Prev])) | AQ4: =IF([@StartMRR]="", "", IF([@StartMRR]<1000, "N/A", ([@StartMRR]+[@Expansion]-[@Contraction]-[@Churn]) / [@StartMRR])) | AR4: =IF(OR([@Spend]="",[@NewCustomers]=""), "", IF([@NewCustomers]<=0, "N/A", [@Spend]/[@NewCustomers])) | AS4: =IF(OR([@ARPA]="",[@GM]="",[@ChurnRate]=""), "", IF([@ChurnRate]<=0, "N/A", [@ARPA]*[@GM]/[@ChurnRate])) | AT4: =IF(OR([@ARPA]="",[@GM]=""), "", IF(([@ARPA]*[@GM])<=0, "N/A", 200/([@ARPA]*[@GM]))) | AU4: =IF([@App_ARR]="","",IF(ABS([@App_ARR]-[@Calc_ARR])<0.01,"PASS","FAIL")) | AV4: =IF([@App_GM]="","",IF(ABS([@App_GM]-[@Calc_GM])<0.0001,"PASS","FAIL")) | AW4: =IF([@App_Burn]="","",IF(ABS([@App_Burn]-[@Calc_Burn])<1,"PASS","FAIL")) | AX4: =IF([@App_Runway]="","",IF(OR(AND([@App_Runway]="Cashflow+",[@Calc_Runway]="Cashflow+"),ABS([@App_Runway]-[@Calc_Runway])<0.01),"PASS","FAIL")) | AY4: =IF([@App_MoMGrowth]="","",IF(OR(AND([@App_MoMGrowth]="N/A",[@Calc_MoMGrowth]="N/A"),ABS([@App_MoMGrowth]-[@Calc_MoMGrowth])<0.0001),"PASS","FAIL")) | AZ4: =IF([@App_NRR]="","",IF(OR(AND([@App_NRR]="N/A",[@Calc_NRR]="N/A"),ABS([@App_NRR]-[@Calc_NRR])<0.0001),"PASS","FAIL")) | BA4: =IF([@App_CAC]="","",IF(OR(AND([@App_CAC]="N/A",[@Calc_CAC]="N/A"),ABS([@App_CAC]-[@Calc_CAC])<0.01),"PASS","FAIL")) | BB4: =IF([@App_LTV]="","",IF(OR(AND([@App_LTV]="N/A",[@Calc_LTV]="N/A"),ABS([@App_LTV]-[@Calc_LTV])<0.01),"PASS","FAIL")) | BC4: =IF([@App_Payback]="","",IF(OR(AND([@App_Payback]="N/A",[@Calc_Payback]="N/A"),ABS([@App_Payback]-[@Calc_Payback])<0.01),"PASS","FAIL"))
A5: TC04_RUNWAY_LOW_CASH | B5: 250000 | C5: 100000 | S5: Low runway = 2.5 months | W5: 2.5 | AL5: =IF([@MRR]="", "", [@MRR]*12) | AM5: =IF(OR([@Revenue]="",[@Revenue]<=0), "", ([@Revenue]-[@COGS]) / [@Revenue]) | AN5: =IF(OR([@Revenue]="",[@OpEx]="",[@COGS]=""), "", MAX(0, [@OpEx]+[@COGS]-[@Revenue])) | AO5: =IF([@Cash]="", "", IF(OR([@Burn]="",[@Burn]=0), IF([@Calc_Burn]="", "", IF([@Calc_Burn]<=0, "Cashflow+", [@Cash]/[@Calc_Burn])), IF([@Burn]<=0, "Cashflow+", [@Cash]/[@Burn]))) | AP5: =IF(OR([@Prev]="",[@Curr]=""), "", IF([@Prev]<1000, "N/A", ([@Curr]-[@Prev]) / [@Prev])) | AQ5: =IF([@StartMRR]="", "", IF([@StartMRR]<1000, "N/A", ([@StartMRR]+[@Expansion]-[@Contraction]-[@Churn]) / [@StartMRR])) | AR5: =IF(OR([@Spend]="",[@NewCustomers]=""), "", IF([@NewCustomers]<=0, "N/A", [@Spend]/[@NewCustomers])) | AS5: =IF(OR([@ARPA]="",[@GM]="",[@ChurnRate]=""), "", IF([@ChurnRate]<=0, "N/A", [@ARPA]*[@GM]/[@ChurnRate])) | AT5: =IF(OR([@ARPA]="",[@GM]=""), "", IF(([@ARPA]*[@GM])<=0, "N/A", 200/([@ARPA]*[@GM]))) | AU5: =IF([@App_ARR]="","",IF(ABS([@App_ARR]-[@Calc_ARR])<0.01,"PASS","FAIL")) | AV5: =IF([@App_GM]="","",IF(ABS([@App_GM]-[@Calc_GM])<0.0001,"PASS","FAIL")) | AW5: =IF([@App_Burn]="","",IF(ABS([@App_Burn]-[@Calc_Burn])<1,"PASS","FAIL")) | AX5: =IF([@App_Runway]="","",IF(OR(AND([@App_Runway]="Cashflow+",[@Calc_Runway]="Cashflow+"),ABS([@App_Runway]-[@Calc_Runway])<0.01),"PASS","FAIL")) | AY5: =IF([@App_MoMGrowth]="","",IF(OR(AND([@App_MoMGrowth]="N/A",[@Calc_MoMGrowth]="N/A"),ABS([@App_MoMGrowth]-[@Calc_MoMGrowth])<0.0001),"PASS","FAIL")) | AZ5: =IF([@App_NRR]="","",IF(OR(AND([@App_NRR]="N/A",[@Calc_NRR]="N/A"),ABS([@App_NRR]-[@Calc_NRR])<0.0001),"PASS","FAIL")) | BA5: =IF([@App_CAC]="","",IF(OR(AND([@App_CAC]="N/A",[@Calc_CAC]="N/A"),ABS([@App_CAC]-[@Calc_CAC])<0.01),"PASS","FAIL")) | BB5: =IF([@App_LTV]="","",IF(OR(AND([@App_LTV]="N/A",[@Calc_LTV]="N/A"),ABS([@App_LTV]-[@Calc_LTV])<0.01),"PASS","FAIL")) | BC5: =IF([@App_Payback]="","",IF(OR(AND([@App_Payback]="N/A",[@Calc_Payback]="N/A"),ABS([@App_Payback]-[@Calc_Payback])<0.01),"PASS","FAIL"))
A6: TC05_RUNWAY_ROUNDING | B6: 1000000 | C6: 84925 | S6: Runway rounding test | W6: 11.775096 | AL6: =IF([@MRR]="", "", [@MRR]*12) | AM6: =IF(OR([@Revenue]="",[@Revenue]<=0), "", ([@Revenue]-[@COGS]) / [@Revenue]) | AN6: =IF(OR([@Revenue]="",[@OpEx]="",[@COGS]=""), "", MAX(0, [@OpEx]+[@COGS]-[@Revenue])) | AO6: =IF([@Cash]="", "", IF(OR([@Burn]="",[@Burn]=0), IF([@Calc_Burn]="", "", IF([@Calc_Burn]<=0, "Cashflow+", [@Cash]/[@Calc_Burn])), IF([@Burn]<=0, "Cashflow+", [@Cash]/[@Burn]))) | AP6: =IF(OR([@Prev]="",[@Curr]=""), "", IF([@Prev]<1000, "N/A", ([@Curr]-[@Prev]) / [@Prev])) | AQ6: =IF([@StartMRR]="", "", IF([@StartMRR]<1000, "N/A", ([@StartMRR]+[@Expansion]-[@Contraction]-[@Churn]) / [@StartMRR])) | AR6: =IF(OR([@Spend]="",[@NewCustomers]=""), "", IF([@NewCustomers]<=0, "N/A", [@Spend]/[@NewCustomers])) | AS6: =IF(OR([@ARPA]="",[@GM]="",[@ChurnRate]=""), "", IF([@ChurnRate]<=0, "N/A", [@ARPA]*[@GM]/[@ChurnRate])) | AT6: =IF(OR([@ARPA]="",[@GM]=""), "", IF(([@ARPA]*[@GM])<=0, "N/A", 200/([@ARPA]*[@GM]))) | AU6: =IF([@App_ARR]="","",IF(ABS([@App_ARR]-[@Calc_ARR])<0.01,"PASS","FAIL")) | AV6: =IF([@App_GM]="","",IF(ABS([@App_GM]-[@Calc_GM])<0.0001,"PASS","FAIL")) | AW6: =IF([@App_Burn]="","",IF(ABS([@App_Burn]-[@Calc_Burn])<1,"PASS","FAIL")) | AX6: =IF([@App_Runway]="","",IF(OR(AND([@App_Runway]="Cashflow+",[@Calc_Runway]="Cashflow+"),ABS([@App_Runway]-[@Calc_Runway])<0.01),"PASS","FAIL")) | AY6: =IF([@App_MoMGrowth]="","",IF(OR(AND([@App_MoMGrowth]="N/A",[@Calc_MoMGrowth]="N/A"),ABS([@App_MoMGrowth]-[@Calc_MoMGrowth])<0.0001),"PASS","FAIL")) | AZ6: =IF([@App_NRR]="","",IF(OR(AND([@App_NRR]="N/A",[@Calc_NRR]="N/A"),ABS([@App_NRR]-[@Calc_NRR])<0.0001),"PASS","FAIL")) | BA6: =IF([@App_CAC]="","",IF(OR(AND([@App_CAC]="N/A",[@Calc_CAC]="N/A"),ABS([@App_CAC]-[@Calc_CAC])<0.01),"PASS","FAIL")) | BB6: =IF([@App_LTV]="","",IF(OR(AND([@App_LTV]="N/A",[@Calc_LTV]="N/A"),ABS([@App_LTV]-[@Calc_LTV])<0.01),"PASS","FAIL")) | BC6: =IF([@App_Payback]="","",IF(OR(AND([@App_Payback]="N/A",[@Calc_Payback]="N/A"),ABS([@App_Payback]-[@Calc_Payback])<0.01),"PASS","FAIL"))
A7: TC06_ARR_BASIC | D7: 520000 | S7: ARR = MRR*12 | T7: 6240000 | AL7: =IF([@MRR]="", "", [@MRR]*12) | AM7: =IF(OR([@Revenue]="",[@Revenue]<=0), "", ([@Revenue]-[@COGS]) / [@Revenue]) | AN7: =IF(OR([@Revenue]="",[@OpEx]="",[@COGS]=""), "", MAX(0, [@OpEx]+[@COGS]-[@Revenue])) | AO7: =IF([@Cash]="", "", IF(OR([@Burn]="",[@Burn]=0), IF([@Calc_Burn]="", "", IF([@Calc_Burn]<=0, "Cashflow+", [@Cash]/[@Calc_Burn])), IF([@Burn]<=0, "Cashflow+", [@Cash]/[@Burn]))) | AP7: =IF(OR([@Prev]="",[@Curr]=""), "", IF([@Prev]<1000, "N/A", ([@Curr]-[@Prev]) / [@Prev])) | AQ7: =IF([@StartMRR]="", "", IF([@StartMRR]<1000, "N/A", ([@StartMRR]+[@Expansion]-[@Contraction]-[@Churn]) / [@StartMRR])) | AR7: =IF(OR([@Spend]="",[@NewCustomers]=""), "", IF([@NewCustomers]<=0, "N/A", [@Spend]/[@NewCustomers])) | AS7: =IF(OR([@ARPA]="",[@GM]="",[@ChurnRate]=""), "", IF([@ChurnRate]<=0, "N/A", [@ARPA]*[@GM]/[@ChurnRate])) | AT7: =IF(OR([@ARPA]="",[@GM]=""), "", IF(([@ARPA]*[@GM])<=0, "N/A", 200/([@ARPA]*[@GM]))) | AU7: =IF([@App_ARR]="","",IF(ABS([@App_ARR]-[@Calc_ARR])<0.01,"PASS","FAIL")) | AV7: =IF([@App_GM]="","",IF(ABS([@App_GM]-[@Calc_GM])<0.0001,"PASS","FAIL")) | AW7: =IF([@App_Burn]="","",IF(ABS([@App_Burn]-[@Calc_Burn])<1,"PASS","FAIL")) | AX7: =IF([@App_Runway]="","",IF(OR(AND([@App_Runway]="Cashflow+",[@Calc_Runway]="Cashflow+"),ABS([@App_Runway]-[@Calc_Runway])<0.01),"PASS","FAIL")) | AY7: =IF([@App_MoMGrowth]="","",IF(OR(AND([@App_MoMGrowth]="N/A",[@Calc_MoMGrowth]="N/A"),ABS([@App_MoMGrowth]-[@Calc_MoMGrowth])<0.0001),"PASS","FAIL")) | AZ7: =IF([@App_NRR]="","",IF(OR(AND([@App_NRR]="N/A",[@Calc_NRR]="N/A"),ABS([@App_NRR]-[@Calc_NRR])<0.0001),"PASS","FAIL")) | BA7: =IF([@App_CAC]="","",IF(OR(AND([@App_CAC]="N/A",[@Calc_CAC]="N/A"),ABS([@App_CAC]-[@Calc_CAC])<0.01),"PASS","FAIL")) | BB7: =IF([@App_LTV]="","",IF(OR(AND([@App_LTV]="N/A",[@Calc_LTV]="N/A"),ABS([@App_LTV]-[@Calc_LTV])<0.01),"PASS","FAIL")) | BC7: =IF([@App_Payback]="","",IF(OR(AND([@App_Payback]="N/A",[@Calc_Payback]="N/A"),ABS([@App_Payback]-[@Calc_Payback])<0.01),"PASS","FAIL"))
A8: TC07_ARR_ZERO | D8: 0 | S8: MRR=0 => ARR=0 | T8: 0 | AL8: =IF([@MRR]="", "", [@MRR]*12) | AM8: =IF(OR([@Revenue]="",[@Revenue]<=0), "", ([@Revenue]-[@COGS]) / [@Revenue]) | AN8: =IF(OR([@Revenue]="",[@OpEx]="",[@COGS]=""), "", MAX(0, [@OpEx]+[@COGS]-[@Revenue])) | AO8: =IF([@Cash]="", "", IF(OR([@Burn]="",[@Burn]=0), IF([@Calc_Burn]="", "", IF([@Calc_Burn]<=0, "Cashflow+", [@Cash]/[@Calc_Burn])), IF([@Burn]<=0, "Cashflow+", [@Cash]/[@Burn]))) | AP8: =IF(OR([@Prev]="",[@Curr]=""), "", IF([@Prev]<1000, "N/A", ([@Curr]-[@Prev]) / [@Prev])) | AQ8: =IF([@StartMRR]="", "", IF([@StartMRR]<1000, "N/A", ([@StartMRR]+[@Expansion]-[@Contraction]-[@Churn]) / [@StartMRR])) | AR8: =IF(OR([@Spend]="",[@NewCustomers]=""), "", IF([@NewCustomers]<=0, "N/A", [@Spend]/[@NewCustomers])) | AS8: =IF(OR([@ARPA]="",[@GM]="",[@ChurnRate]=""), "", IF([@ChurnRate]<=0, "N/A", [@ARPA]*[@GM]/[@ChurnRate])) | AT8: =IF(OR([@ARPA]="",[@GM]=""), "", IF(([@ARPA]*[@GM])<=0, "N/A", 200/([@ARPA]*[@GM]))) | AU8: =IF([@App_ARR]="","",IF(ABS([@App_ARR]-[@Calc_ARR])<0.01,"PASS","FAIL")) | AV8: =IF([@App_GM]="","",IF(ABS([@App_GM]-[@Calc_GM])<0.0001,"PASS","FAIL")) | AW8: =IF([@App_Burn]="","",IF(ABS([@App_Burn]-[@Calc_Burn])<1,"PASS","FAIL")) | AX8: =IF([@App_Runway]="","",IF(OR(AND([@App_Runway]="Cashflow+",[@Calc_Runway]="Cashflow+"),ABS([@App_Runway]-[@Calc_Runway])<0.01),"PASS","FAIL")) | AY8: =IF([@App_MoMGrowth]="","",IF(OR(AND([@App_MoMGrowth]="N/A",[@Calc_MoMGrowth]="N/A"),ABS([@App_MoMGrowth]-[@Calc_MoMGrowth])<0.0001),"PASS","FAIL")) | AZ8: =IF([@App_NRR]="","",IF(OR(AND([@App_NRR]="N/A",[@Calc_NRR]="N/A"),ABS([@App_NRR]-[@Calc_NRR])<0.0001),"PASS","FAIL")) | BA8: =IF([@App_CAC]="","",IF(OR(AND([@App_CAC]="N/A",[@Calc_CAC]="N/A"),ABS([@App_CAC]-[@Calc_CAC])<0.01),"PASS","FAIL")) | BB8: =IF([@App_LTV]="","",IF(OR(AND([@App_LTV]="N/A",[@Calc_LTV]="N/A"),ABS([@App_LTV]-[@Calc_LTV])<0.01),"PASS","FAIL")) | BC8: =IF([@App_Payback]="","",IF(OR(AND([@App_Payback]="N/A",[@Calc_Payback]="N/A"),ABS([@App_Payback]-[@Calc_Payback])<0.01),"PASS","FAIL"))
A9: TC08_ARR_MRR_MISSING | S9: Missing MRR => ARR blank | AL9: =IF([@MRR]="", "", [@MRR]*12) | AM9: =IF(OR([@Revenue]="",[@Revenue]<=0), "", ([@Revenue]-[@COGS]) / [@Revenue]) | AN9: =IF(OR([@Revenue]="",[@OpEx]="",[@COGS]=""), "", MAX(0, [@OpEx]+[@COGS]-[@Revenue])) | AO9: =IF([@Cash]="", "", IF(OR([@Burn]="",[@Burn]=0), IF([@Calc_Burn]="", "", IF([@Calc_Burn]<=0, "Cashflow+", [@Cash]/[@Calc_Burn])), IF([@Burn]<=0, "Cashflow+", [@Cash]/[@Burn]))) | AP9: =IF(OR([@Prev]="",[@Curr]=""), "", IF([@Prev]<1000, "N/A", ([@Curr]-[@Prev]) / [@Prev])) | AQ9: =IF([@StartMRR]="", "", IF([@StartMRR]<1000, "N/A", ([@StartMRR]+[@Expansion]-[@Contraction]-[@Churn]) / [@StartMRR])) | AR9: =IF(OR([@Spend]="",[@NewCustomers]=""), "", IF([@NewCustomers]<=0, "N/A", [@Spend]/[@NewCustomers])) | AS9: =IF(OR([@ARPA]="",[@GM]="",[@ChurnRate]=""), "", IF([@ChurnRate]<=0, "N/A", [@ARPA]*[@GM]/[@ChurnRate])) | AT9: =IF(OR([@ARPA]="",[@GM]=""), "", IF(([@ARPA]*[@GM])<=0, "N/A", 200/([@ARPA]*[@GM]))) | AU9: =IF([@App_ARR]="","",IF(ABS([@App_ARR]-[@Calc_ARR])<0.01,"PASS","FAIL")) | AV9: =IF([@App_GM]="","",IF(ABS([@App_GM]-[@Calc_GM])<0.0001,"PASS","FAIL")) | AW9: =IF([@App_Burn]="","",IF(ABS([@App_Burn]-[@Calc_Burn])<1,"PASS","FAIL")) | AX9: =IF([@App_Runway]="","",IF(OR(AND([@App_Runway]="Cashflow+",[@Calc_Runway]="Cashflow+"),ABS([@App_Runway]-[@Calc_Runway])<0.01),"PASS","FAIL")) | AY9: =IF([@App_MoMGrowth]="","",IF(OR(AND([@App_MoMGrowth]="N/A",[@Calc_MoMGrowth]="N/A"),ABS([@App_MoMGrowth]-[@Calc_MoMGrowth])<0.0001),"PASS","FAIL")) | AZ9: =IF([@App_NRR]="","",IF(OR(AND([@App_NRR]="N/A",[@Calc_NRR]="N/A"),ABS([@App_NRR]-[@Calc_NRR])<0.0001),"PASS","FAIL")) | BA9: =IF([@App_CAC]="","",IF(OR(AND([@App_CAC]="N/A",[@Calc_CAC]="N/A"),ABS([@App_CAC]-[@Calc_CAC])<0.01),"PASS","FAIL")) | BB9: =IF([@App_LTV]="","",IF(OR(AND([@App_LTV]="N/A",[@Calc_LTV]="N/A"),ABS([@App_LTV]-[@Calc_LTV])<0.01),"PASS","FAIL")) | BC9: =IF([@App_Payback]="","",IF(OR(AND([@App_Payback]="N/A",[@Calc_Payback]="N/A"),ABS([@App_Payback]-[@Calc_Payback])<0.01),"PASS","FAIL"))
A10: TC09_GM_BASIC | E10: 1000000 | F10: 200000 | S10: GM% = 0.8 | U10: 0.8 | AL10: =IF([@MRR]="", "", [@MRR]*12) | AM10: =IF(OR([@Revenue]="",[@Revenue]<=0), "", ([@Revenue]-[@COGS]) / [@Revenue]) | AN10: =IF(OR([@Revenue]="",[@OpEx]="",[@COGS]=""), "", MAX(0, [@OpEx]+[@COGS]-[@Revenue])) | AO10: =IF([@Cash]="", "", IF(OR([@Burn]="",[@Burn]=0), IF([@Calc_Burn]="", "", IF([@Calc_Burn]<=0, "Cashflow+", [@Cash]/[@Calc_Burn])), IF([@Burn]<=0, "Cashflow+", [@Cash]/[@Burn]))) | AP10: =IF(OR([@Prev]="",[@Curr]=""), "", IF([@Prev]<1000, "N/A", ([@Curr]-[@Prev]) / [@Prev])) | AQ10: =IF([@StartMRR]="", "", IF([@StartMRR]<1000, "N/A", ([@StartMRR]+[@Expansion]-[@Contraction]-[@Churn]) / [@StartMRR])) | AR10: =IF(OR([@Spend]="",[@NewCustomers]=""), "", IF([@NewCustomers]<=0, "N/A", [@Spend]/[@NewCustomers])) | AS10: =IF(OR([@ARPA]="",[@GM]="",[@ChurnRate]=""), "", IF([@ChurnRate]<=0, "N/A", [@ARPA]*[@GM]/[@ChurnRate])) | AT10: =IF(OR([@ARPA]="",[@GM]=""), "", IF(([@ARPA]*[@GM])<=0, "N/A", 200/([@ARPA]*[@GM]))) | AU10: =IF([@App_ARR]="","",IF(ABS([@App_ARR]-[@Calc_ARR])<0.01,"PASS","FAIL")) | AV10: =IF([@App_GM]="","",IF(ABS([@App_GM]-[@Calc_GM])<0.0001,"PASS","FAIL")) | AW10: =IF([@App_Burn]="","",IF(ABS([@App_Burn]-[@Calc_Burn])<1,"PASS","FAIL")) | AX10: =IF([@App_Runway]="","",IF(OR(AND([@App_Runway]="Cashflow+",[@Calc_Runway]="Cashflow+"),ABS([@App_Runway]-[@Calc_Runway])<0.01),"PASS","FAIL")) | AY10: =IF([@App_MoMGrowth]="","",IF(OR(AND([@App_MoMGrowth]="N/A",[@Calc_MoMGrowth]="N/A"),ABS([@App_MoMGrowth]-[@Calc_MoMGrowth])<0.0001),"PASS","FAIL")) | AZ10: =IF([@App_NRR]="","",IF(OR(AND([@App_NRR]="N/A",[@Calc_NRR]="N/A"),ABS([@App_NRR]-[@Calc_NRR])<0.0001),"PASS","FAIL")) | BA10: =IF([@App_CAC]="","",IF(OR(AND([@App_CAC]="N/A",[@Calc_CAC]="N/A"),ABS([@App_CAC]-[@Calc_CAC])<0.01),"PASS","FAIL")) | BB10: =IF([@App_LTV]="","",IF(OR(AND([@App_LTV]="N/A",[@Calc_LTV]="N/A"),ABS([@App_LTV]-[@Calc_LTV])<0.01),"PASS","FAIL")) | BC10: =IF([@App_Payback]="","",IF(OR(AND([@App_Payback]="N/A",[@Calc_Payback]="N/A"),ABS([@App_Payback]-[@Calc_Payback])<0.01),"PASS","FAIL"))
A11: TC10_GM_REVENUE_ZERO | E11: 0 | F11: 200000 | S11: Revenue<=0 => GM N/A | AL11: =IF([@MRR]="", "", [@MRR]*12) | AM11: =IF(OR([@Revenue]="",[@Revenue]<=0), "", ([@Revenue]-[@COGS]) / [@Revenue]) | AN11: =IF(OR([@Revenue]="",[@OpEx]="",[@COGS]=""), "", MAX(0, [@OpEx]+[@COGS]-[@Revenue])) | AO11: =IF([@Cash]="", "", IF(OR([@Burn]="",[@Burn]=0), IF([@Calc_Burn]="", "", IF([@Calc_Burn]<=0, "Cashflow+", [@Cash]/[@Calc_Burn])), IF([@Burn]<=0, "Cashflow+", [@Cash]/[@Burn]))) | AP11: =IF(OR([@Prev]="",[@Curr]=""), "", IF([@Prev]<1000, "N/A", ([@Curr]-[@Prev]) / [@Prev])) | AQ11: =IF([@StartMRR]="", "", IF([@StartMRR]<1000, "N/A", ([@StartMRR]+[@Expansion]-[@Contraction]-[@Churn]) / [@StartMRR])) | AR11: =IF(OR([@Spend]="",[@NewCustomers]=""), "", IF([@NewCustomers]<=0, "N/A", [@Spend]/[@NewCustomers])) | AS11: =IF(OR([@ARPA]="",[@GM]="",[@ChurnRate]=""), "", IF([@ChurnRate]<=0, "N/A", [@ARPA]*[@GM]/[@ChurnRate])) | AT11: =IF(OR([@ARPA]="",[@GM]=""), "", IF(([@ARPA]*[@GM])<=0, "N/A", 200/([@ARPA]*[@GM]))) | AU11: =IF([@App_ARR]="","",IF(ABS([@App_ARR]-[@Calc_ARR])<0.01,"PASS","FAIL")) | AV11: =IF([@App_GM]="","",IF(ABS([@App_GM]-[@Calc_GM])<0.0001,"PASS","FAIL")) | AW11: =IF([@App_Burn]="","",IF(ABS([@App_Burn]-[@Calc_Burn])<1,"PASS","FAIL")) | AX11: =IF([@App_Runway]="","",IF(OR(AND([@App_Runway]="Cashflow+",[@Calc_Runway]="Cashflow+"),ABS([@App_Runway]-[@Calc_Runway])<0.01),"PASS","FAIL")) | AY11: =IF([@App_MoMGrowth]="","",IF(OR(AND([@App_MoMGrowth]="N/A",[@Calc_MoMGrowth]="N/A"),ABS([@App_MoMGrowth]-[@Calc_MoMGrowth])<0.0001),"PASS","FAIL")) | AZ11: =IF([@App_NRR]="","",IF(OR(AND([@App_NRR]="N/A",[@Calc_NRR]="N/A"),ABS([@App_NRR]-[@Calc_NRR])<0.0001),"PASS","FAIL")) | BA11: =IF([@App_CAC]="","",IF(OR(AND([@App_CAC]="N/A",[@Calc_CAC]="N/A"),ABS([@App_CAC]-[@Calc_CAC])<0.01),"PASS","FAIL")) | BB11: =IF([@App_LTV]="","",IF(OR(AND([@App_LTV]="N/A",[@Calc_LTV]="N/A"),ABS([@App_LTV]-[@Calc_LTV])<0.01),"PASS","FAIL")) | BC11: =IF([@App_Payback]="","",IF(OR(AND([@App_Payback]="N/A",[@Calc_Payback]="N/A"),ABS([@App_Payback]-[@Calc_Payback])<0.01),"PASS","FAIL"))
A12: TC11_GM_REVENUE_NEG | E12: -100 | F12: 10 | S12: Negative revenue => GM N/A | AL12: =IF([@MRR]="", "", [@MRR]*12) | AM12: =IF(OR([@Revenue]="",[@Revenue]<=0), "", ([@Revenue]-[@COGS]) / [@Revenue]) | AN12: =IF(OR([@Revenue]="",[@OpEx]="",[@COGS]=""), "", MAX(0, [@OpEx]+[@COGS]-[@Revenue])) | AO12: =IF([@Cash]="", "", IF(OR([@Burn]="",[@Burn]=0), IF([@Calc_Burn]="", "", IF([@Calc_Burn]<=0, "Cashflow+", [@Cash]/[@Calc_Burn])), IF([@Burn]<=0, "Cashflow+", [@Cash]/[@Burn]))) | AP12: =IF(OR([@Prev]="",[@Curr]=""), "", IF([@Prev]<1000, "N/A", ([@Curr]-[@Prev]) / [@Prev])) | AQ12: =IF([@StartMRR]="", "", IF([@StartMRR]<1000, "N/A", ([@StartMRR]+[@Expansion]-[@Contraction]-[@Churn]) / [@StartMRR])) | AR12: =IF(OR([@Spend]="",[@NewCustomers]=""), "", IF([@NewCustomers]<=0, "N/A", [@Spend]/[@NewCustomers])) | AS12: =IF(OR([@ARPA]="",[@GM]="",[@ChurnRate]=""), "", IF([@ChurnRate]<=0, "N/A", [@ARPA]*[@GM]/[@ChurnRate])) | AT12: =IF(OR([@ARPA]="",[@GM]=""), "", IF(([@ARPA]*[@GM])<=0, "N/A", 200/([@ARPA]*[@GM]))) | AU12: =IF([@App_ARR]="","",IF(ABS([@App_ARR]-[@Calc_ARR])<0.01,"PASS","FAIL")) | AV12: =IF([@App_GM]="","",IF(ABS([@App_GM]-[@Calc_GM])<0.0001,"PASS","FAIL")) | AW12: =IF([@App_Burn]="","",IF(ABS([@App_Burn]-[@Calc_Burn])<1,"PASS","FAIL")) | AX12: =IF([@App_Runway]="","",IF(OR(AND([@App_Runway]="Cashflow+",[@Calc_Runway]="Cashflow+"),ABS([@App_Runway]-[@Calc_Runway])<0.01),"PASS","FAIL")) | AY12: =IF([@App_MoMGrowth]="","",IF(OR(AND([@App_MoMGrowth]="N/A",[@Calc_MoMGrowth]="N/A"),ABS([@App_MoMGrowth]-[@Calc_MoMGrowth])<0.0001),"PASS","FAIL")) | AZ12: =IF([@App_NRR]="","",IF(OR(AND([@App_NRR]="N/A",[@Calc_NRR]="N/A"),ABS([@App_NRR]-[@Calc_NRR])<0.0001),"PASS","FAIL")) | BA12: =IF([@App_CAC]="","",IF(OR(AND([@App_CAC]="N/A",[@Calc_CAC]="N/A"),ABS([@App_CAC]-[@Calc_CAC])<0.01),"PASS","FAIL")) | BB12: =IF([@App_LTV]="","",IF(OR(AND([@App_LTV]="N/A",[@Calc_LTV]="N/A"),ABS([@App_LTV]-[@Calc_LTV])<0.01),"PASS","FAIL")) | BC12: =IF([@App_Payback]="","",IF(OR(AND([@App_Payback]="N/A",[@Calc_Payback]="N/A"),ABS([@App_Payback]-[@Calc_Payback])<0.01),"PASS","FAIL"))
A13: TC12_GM_COGS_GT_REV | E13: 100000 | F13: 150000 | S13: GM negative => allowed output -0.5 | U13: -0.5 | AL13: =IF([@MRR]="", "", [@MRR]*12) | AM13: =IF(OR([@Revenue]="",[@Revenue]<=0), "", ([@Revenue]-[@COGS]) / [@Revenue]) | AN13: =IF(OR([@Revenue]="",[@OpEx]="",[@COGS]=""), "", MAX(0, [@OpEx]+[@COGS]-[@Revenue])) | AO13: =IF([@Cash]="", "", IF(OR([@Burn]="",[@Burn]=0), IF([@Calc_Burn]="", "", IF([@Calc_Burn]<=0, "Cashflow+", [@Cash]/[@Calc_Burn])), IF([@Burn]<=0, "Cashflow+", [@Cash]/[@Burn]))) | AP13: =IF(OR([@Prev]="",[@Curr]=""), "", IF([@Prev]<1000, "N/A", ([@Curr]-[@Prev]) / [@Prev])) | AQ13: =IF([@StartMRR]="", "", IF([@StartMRR]<1000, "N/A", ([@StartMRR]+[@Expansion]-[@Contraction]-[@Churn]) / [@StartMRR])) | AR13: =IF(OR([@Spend]="",[@NewCustomers]=""), "", IF([@NewCustomers]<=0, "N/A", [@Spend]/[@NewCustomers])) | AS13: =IF(OR([@ARPA]="",[@GM]="",[@ChurnRate]=""), "", IF([@ChurnRate]<=0, "N/A", [@ARPA]*[@GM]/[@ChurnRate])) | AT13: =IF(OR([@ARPA]="",[@GM]=""), "", IF(([@ARPA]*[@GM])<=0, "N/A", 200/([@ARPA]*[@GM]))) | AU13: =IF([@App_ARR]="","",IF(ABS([@App_ARR]-[@Calc_ARR])<0.01,"PASS","FAIL")) | AV13: =IF([@App_GM]="","",IF(ABS([@App_GM]-[@Calc_GM])<0.0001,"PASS","FAIL")) | AW13: =IF([@App_Burn]="","",IF(ABS([@App_Burn]-[@Calc_Burn])<1,"PASS","FAIL")) | AX13: =IF([@App_Runway]="","",IF(OR(AND([@App_Runway]="Cashflow+",[@Calc_Runway]="Cashflow+"),ABS([@App_Runway]-[@Calc_Runway])<0.01),"PASS","FAIL")) | AY13: =IF([@App_MoMGrowth]="","",IF(OR(AND([@App_MoMGrowth]="N/A",[@Calc_MoMGrowth]="N/A"),ABS([@App_MoMGrowth]-[@Calc_MoMGrowth])<0.0001),"PASS","FAIL")) | AZ13: =IF([@App_NRR]="","",IF(OR(AND([@App_NRR]="N/A",[@Calc_NRR]="N/A"),ABS([@App_NRR]-[@Calc_NRR])<0.0001),"PASS","FAIL")) | BA13: =IF([@App_CAC]="","",IF(OR(AND([@App_CAC]="N/A",[@Calc_CAC]="N/A"),ABS([@App_CAC]-[@Calc_CAC])<0.01),"PASS","FAIL")) | BB13: =IF([@App_LTV]="","",IF(OR(AND([@App_LTV]="N/A",[@Calc_LTV]="N/A"),ABS([@App_LTV]-[@Calc_LTV])<0.01),"PASS","FAIL")) | BC13: =IF([@App_Payback]="","",IF(OR(AND([@App_Payback]="N/A",[@Calc_Payback]="N/A"),ABS([@App_Payback]-[@Calc_Payback])<0.01),"PASS","FAIL"))
A14: TC13_BURN_BASIC | B14: 4000000 | E14: 1000000 | F14: 300000 | G14: 900000 | S14: Burn=max(0,OpEx+COGS-Revenue)=200k | U14: 0.7 | V14: 200000 | W14: 20 | AL14: =IF([@MRR]="", "", [@MRR]*12) | AM14: =IF(OR([@Revenue]="",[@Revenue]<=0), "", ([@Revenue]-[@COGS]) / [@Revenue]) | AN14: =IF(OR([@Revenue]="",[@OpEx]="",[@COGS]=""), "", MAX(0, [@OpEx]+[@COGS]-[@Revenue])) | AO14: =IF([@Cash]="", "", IF(OR([@Burn]="",[@Burn]=0), IF([@Calc_Burn]="", "", IF([@Calc_Burn]<=0, "Cashflow+", [@Cash]/[@Calc_Burn])), IF([@Burn]<=0, "Cashflow+", [@Cash]/[@Burn]))) | AP14: =IF(OR([@Prev]="",[@Curr]=""), "", IF([@Prev]<1000, "N/A", ([@Curr]-[@Prev]) / [@Prev])) | AQ14: =IF([@StartMRR]="", "", IF([@StartMRR]<1000, "N/A", ([@StartMRR]+[@Expansion]-[@Contraction]-[@Churn]) / [@StartMRR])) | AR14: =IF(OR([@Spend]="",[@NewCustomers]=""), "", IF([@NewCustomers]<=0, "N/A", [@Spend]/[@NewCustomers])) | AS14: =IF(OR([@ARPA]="",[@GM]="",[@ChurnRate]=""), "", IF([@ChurnRate]<=0, "N/A", [@ARPA]*[@GM]/[@ChurnRate])) | AT14: =IF(OR([@ARPA]="",[@GM]=""), "", IF(([@ARPA]*[@GM])<=0, "N/A", 200/([@ARPA]*[@GM]))) | AU14: =IF([@App_ARR]="","",IF(ABS([@App_ARR]-[@Calc_ARR])<0.01,"PASS","FAIL")) | AV14: =IF([@App_GM]="","",IF(ABS([@App_GM]-[@Calc_GM])<0.0001,"PASS","FAIL")) | AW14: =IF([@App_Burn]="","",IF(ABS([@App_Burn]-[@Calc_Burn])<1,"PASS","FAIL")) | AX14: =IF([@App_Runway]="","",IF(OR(AND([@App_Runway]="Cashflow+",[@Calc_Runway]="Cashflow+"),ABS([@App_Runway]-[@Calc_Runway])<0.01),"PASS","FAIL")) | AY14: =IF([@App_MoMGrowth]="","",IF(OR(AND([@App_MoMGrowth]="N/A",[@Calc_MoMGrowth]="N/A"),ABS([@App_MoMGrowth]-[@Calc_MoMGrowth])<0.0001),"PASS","FAIL")) | AZ14: =IF([@App_NRR]="","",IF(OR(AND([@App_NRR]="N/A",[@Calc_NRR]="N/A"),ABS([@App_NRR]-[@Calc_NRR])<0.0001),"PASS","FAIL")) | BA14: =IF([@App_CAC]="","",IF(OR(AND([@App_CAC]="N/A",[@Calc_CAC]="N/A"),ABS([@App_CAC]-[@Calc_CAC])<0.01),"PASS","FAIL")) | BB14: =IF([@App_LTV]="","",IF(OR(AND([@App_LTV]="N/A",[@Calc_LTV]="N/A"),ABS([@App_LTV]-[@Calc_LTV])<0.01),"PASS","FAIL")) | BC14: =IF([@App_Payback]="","",IF(OR(AND([@App_Payback]="N/A",[@Calc_Payback]="N/A"),ABS([@App_Payback]-[@Calc_Payback])<0.01),"PASS","FAIL"))
A15: TC14_BURN_ZERO | B15: 4000000 | E15: 1200000 | F15: 200000 | G15: 900000 | S15: Cashflow positive => burn=0 | U15: 0.83333333 | V15: 0 | W15: Cashflow+ | AL15: =IF([@MRR]="", "", [@MRR]*12) | AM15: =IF(OR([@Revenue]="",[@Revenue]<=0), "", ([@Revenue]-[@COGS]) / [@Revenue]) | AN15: =IF(OR([@Revenue]="",[@OpEx]="",[@COGS]=""), "", MAX(0, [@OpEx]+[@COGS]-[@Revenue])) | AO15: =IF([@Cash]="", "", IF(OR([@Burn]="",[@Burn]=0), IF([@Calc_Burn]="", "", IF([@Calc_Burn]<=0, "Cashflow+", [@Cash]/[@Calc_Burn])), IF([@Burn]<=0, "Cashflow+", [@Cash]/[@Burn]))) | AP15: =IF(OR([@Prev]="",[@Curr]=""), "", IF([@Prev]<1000, "N/A", ([@Curr]-[@Prev]) / [@Prev])) | AQ15: =IF([@StartMRR]="", "", IF([@StartMRR]<1000, "N/A", ([@StartMRR]+[@Expansion]-[@Contraction]-[@Churn]) / [@StartMRR])) | AR15: =IF(OR([@Spend]="",[@NewCustomers]=""), "", IF([@NewCustomers]<=0, "N/A", [@Spend]/[@NewCustomers])) | AS15: =IF(OR([@ARPA]="",[@GM]="",[@ChurnRate]=""), "", IF([@ChurnRate]<=0, "N/A", [@ARPA]*[@GM]/[@ChurnRate])) | AT15: =IF(OR([@ARPA]="",[@GM]=""), "", IF(([@ARPA]*[@GM])<=0, "N/A", 200/([@ARPA]*[@GM]))) | AU15: =IF([@App_ARR]="","",IF(ABS([@App_ARR]-[@Calc_ARR])<0.01,"PASS","FAIL")) | AV15: =IF([@App_GM]="","",IF(ABS([@App_GM]-[@Calc_GM])<0.0001,"PASS","FAIL")) | AW15: =IF([@App_Burn]="","",IF(ABS([@App_Burn]-[@Calc_Burn])<1,"PASS","FAIL")) | AX15: =IF([@App_Runway]="","",IF(OR(AND([@App_Runway]="Cashflow+",[@Calc_Runway]="Cashflow+"),ABS([@App_Runway]-[@Calc_Runway])<0.01),"PASS","FAIL")) | AY15: =IF([@App_MoMGrowth]="","",IF(OR(AND([@App_MoMGrowth]="N/A",[@Calc_MoMGrowth]="N/A"),ABS([@App_MoMGrowth]-[@Calc_MoMGrowth])<0.0001),"PASS","FAIL")) | AZ15: =IF([@App_NRR]="","",IF(OR(AND([@App_NRR]="N/A",[@Calc_NRR]="N/A"),ABS([@App_NRR]-[@Calc_NRR])<0.0001),"PASS","FAIL")) | BA15: =IF([@App_CAC]="","",IF(OR(AND([@App_CAC]="N/A",[@Calc_CAC]="N/A"),ABS([@App_CAC]-[@Calc_CAC])<0.01),"PASS","FAIL")) | BB15: =IF([@App_LTV]="","",IF(OR(AND([@App_LTV]="N/A",[@Calc_LTV]="N/A"),ABS([@App_LTV]-[@Calc_LTV])<0.01),"PASS","FAIL")) | BC15: =IF([@App_Payback]="","",IF(OR(AND([@App_Payback]="N/A",[@Calc_Payback]="N/A"),ABS([@App_Payback]-[@Calc_Payback])<0.01),"PASS","FAIL"))
A16: TC15_BURN_MISSING_INPUTS | S16: Missing => burn blank | AL16: =IF([@MRR]="", "", [@MRR]*12) | AM16: =IF(OR([@Revenue]="",[@Revenue]<=0), "", ([@Revenue]-[@COGS]) / [@Revenue]) | AN16: =IF(OR([@Revenue]="",[@OpEx]="",[@COGS]=""), "", MAX(0, [@OpEx]+[@COGS]-[@Revenue])) | AO16: =IF([@Cash]="", "", IF(OR([@Burn]="",[@Burn]=0), IF([@Calc_Burn]="", "", IF([@Calc_Burn]<=0, "Cashflow+", [@Cash]/[@Calc_Burn])), IF([@Burn]<=0, "Cashflow+", [@Cash]/[@Burn]))) | AP16: =IF(OR([@Prev]="",[@Curr]=""), "", IF([@Prev]<1000, "N/A", ([@Curr]-[@Prev]) / [@Prev])) | AQ16: =IF([@StartMRR]="", "", IF([@StartMRR]<1000, "N/A", ([@StartMRR]+[@Expansion]-[@Contraction]-[@Churn]) / [@StartMRR])) | AR16: =IF(OR([@Spend]="",[@NewCustomers]=""), "", IF([@NewCustomers]<=0, "N/A", [@Spend]/[@NewCustomers])) | AS16: =IF(OR([@ARPA]="",[@GM]="",[@ChurnRate]=""), "", IF([@ChurnRate]<=0, "N/A", [@ARPA]*[@GM]/[@ChurnRate])) | AT16: =IF(OR([@ARPA]="",[@GM]=""), "", IF(([@ARPA]*[@GM])<=0, "N/A", 200/([@ARPA]*[@GM]))) | AU16: =IF([@App_ARR]="","",IF(ABS([@App_ARR]-[@Calc_ARR])<0.01,"PASS","FAIL")) | AV16: =IF([@App_GM]="","",IF(ABS([@App_GM]-[@Calc_GM])<0.0001,"PASS","FAIL")) | AW16: =IF([@App_Burn]="","",IF(ABS([@App_Burn]-[@Calc_Burn])<1,"PASS","FAIL")) | AX16: =IF([@App_Runway]="","",IF(OR(AND([@App_Runway]="Cashflow+",[@Calc_Runway]="Cashflow+"),ABS([@App_Runway]-[@Calc_Runway])<0.01),"PASS","FAIL")) | AY16: =IF([@App_MoMGrowth]="","",IF(OR(AND([@App_MoMGrowth]="N/A",[@Calc_MoMGrowth]="N/A"),ABS([@App_MoMGrowth]-[@Calc_MoMGrowth])<0.0001),"PASS","FAIL")) | AZ16: =IF([@App_NRR]="","",IF(OR(AND([@App_NRR]="N/A",[@Calc_NRR]="N/A"),ABS([@App_NRR]-[@Calc_NRR])<0.0001),"PASS","FAIL")) | BA16: =IF([@App_CAC]="","",IF(OR(AND([@App_CAC]="N/A",[@Calc_CAC]="N/A"),ABS([@App_CAC]-[@Calc_CAC])<0.01),"PASS","FAIL")) | BB16: =IF([@App_LTV]="","",IF(OR(AND([@App_LTV]="N/A",[@Calc_LTV]="N/A"),ABS([@App_LTV]-[@Calc_LTV])<0.01),"PASS","FAIL")) | BC16: =IF([@App_Payback]="","",IF(OR(AND([@App_Payback]="N/A",[@Calc_Payback]="N/A"),ABS([@App_Payback]-[@Calc_Payback])<0.01),"PASS","FAIL"))
A17: TC16_MOMGROWTH_NORMAL | H17: 100000 | I17: 110000 | S17: 10% MoM growth | X17: 0.1 | AL17: =IF([@MRR]="", "", [@MRR]*12) | AM17: =IF(OR([@Revenue]="",[@Revenue]<=0), "", ([@Revenue]-[@COGS]) / [@Revenue]) | AN17: =IF(OR([@Revenue]="",[@OpEx]="",[@COGS]=""), "", MAX(0, [@OpEx]+[@COGS]-[@Revenue])) | AO17: =IF([@Cash]="", "", IF(OR([@Burn]="",[@Burn]=0), IF([@Calc_Burn]="", "", IF([@Calc_Burn]<=0, "Cashflow+", [@Cash]/[@Calc_Burn])), IF([@Burn]<=0, "Cashflow+", [@Cash]/[@Burn]))) | AP17: =IF(OR([@Prev]="",[@Curr]=""), "", IF([@Prev]<1000, "N/A", ([@Curr]-[@Prev]) / [@Prev])) | AQ17: =IF([@StartMRR]="", "", IF([@StartMRR]<1000, "N/A", ([@StartMRR]+[@Expansion]-[@Contraction]-[@Churn]) / [@StartMRR])) | AR17: =IF(OR([@Spend]="",[@NewCustomers]=""), "", IF([@NewCustomers]<=0, "N/A", [@Spend]/[@NewCustomers])) | AS17: =IF(OR([@ARPA]="",[@GM]="",[@ChurnRate]=""), "", IF([@ChurnRate]<=0, "N/A", [@ARPA]*[@GM]/[@ChurnRate])) | AT17: =IF(OR([@ARPA]="",[@GM]=""), "", IF(([@ARPA]*[@GM])<=0, "N/A", 200/([@ARPA]*[@GM]))) | AU17: =IF([@App_ARR]="","",IF(ABS([@App_ARR]-[@Calc_ARR])<0.01,"PASS","FAIL")) | AV17: =IF([@App_GM]="","",IF(ABS([@App_GM]-[@Calc_GM])<0.0001,"PASS","FAIL")) | AW17: =IF([@App_Burn]="","",IF(ABS([@App_Burn]-[@Calc_Burn])<1,"PASS","FAIL")) | AX17: =IF([@App_Runway]="","",IF(OR(AND([@App_Runway]="Cashflow+",[@Calc_Runway]="Cashflow+"),ABS([@App_Runway]-[@Calc_Runway])<0.01),"PASS","FAIL")) | AY17: =IF([@App_MoMGrowth]="","",IF(OR(AND([@App_MoMGrowth]="N/A",[@Calc_MoMGrowth]="N/A"),ABS([@App_MoMGrowth]-[@Calc_MoMGrowth])<0.0001),"PASS","FAIL")) | AZ17: =IF([@App_NRR]="","",IF(OR(AND([@App_NRR]="N/A",[@Calc_NRR]="N/A"),ABS([@App_NRR]-[@Calc_NRR])<0.0001),"PASS","FAIL")) | BA17: =IF([@App_CAC]="","",IF(OR(AND([@App_CAC]="N/A",[@Calc_CAC]="N/A"),ABS([@App_CAC]-[@Calc_CAC])<0.01),"PASS","FAIL")) | BB17: =IF([@App_LTV]="","",IF(OR(AND([@App_LTV]="N/A",[@Calc_LTV]="N/A"),ABS([@App_LTV]-[@Calc_LTV])<0.01),"PASS","FAIL")) | BC17: =IF([@App_Payback]="","",IF(OR(AND([@App_Payback]="N/A",[@Calc_Payback]="N/A"),ABS([@App_Payback]-[@Calc_Payback])<0.01),"PASS","FAIL"))
A18: TC17_MOMGROWTH_DENOM_SMALL | H18: 50 | I18: 5000 | S18: Prev<1000 => N/A | X18: N/A | AL18: =IF([@MRR]="", "", [@MRR]*12) | AM18: =IF(OR([@Revenue]="",[@Revenue]<=0), "", ([@Revenue]-[@COGS]) / [@Revenue]) | AN18: =IF(OR([@Revenue]="",[@OpEx]="",[@COGS]=""), "", MAX(0, [@OpEx]+[@COGS]-[@Revenue])) | AO18: =IF([@Cash]="", "", IF(OR([@Burn]="",[@Burn]=0), IF([@Calc_Burn]="", "", IF([@Calc_Burn]<=0, "Cashflow+", [@Cash]/[@Calc_Burn])), IF([@Burn]<=0, "Cashflow+", [@Cash]/[@Burn]))) | AP18: =IF(OR([@Prev]="",[@Curr]=""), "", IF([@Prev]<1000, "N/A", ([@Curr]-[@Prev]) / [@Prev])) | AQ18: =IF([@StartMRR]="", "", IF([@StartMRR]<1000, "N/A", ([@StartMRR]+[@Expansion]-[@Contraction]-[@Churn]) / [@StartMRR])) | AR18: =IF(OR([@Spend]="",[@NewCustomers]=""), "", IF([@NewCustomers]<=0, "N/A", [@Spend]/[@NewCustomers])) | AS18: =IF(OR([@ARPA]="",[@GM]="",[@ChurnRate]=""), "", IF([@ChurnRate]<=0, "N/A", [@ARPA]*[@GM]/[@ChurnRate])) | AT18: =IF(OR([@ARPA]="",[@GM]=""), "", IF(([@ARPA]*[@GM])<=0, "N/A", 200/([@ARPA]*[@GM]))) | AU18: =IF([@App_ARR]="","",IF(ABS([@App_ARR]-[@Calc_ARR])<0.01,"PASS","FAIL")) | AV18: =IF([@App_GM]="","",IF(ABS([@App_GM]-[@Calc_GM])<0.0001,"PASS","FAIL")) | AW18: =IF([@App_Burn]="","",IF(ABS([@App_Burn]-[@Calc_Burn])<1,"PASS","FAIL")) | AX18: =IF([@App_Runway]="","",IF(OR(AND([@App_Runway]="Cashflow+",[@Calc_Runway]="Cashflow+"),ABS([@App_Runway]-[@Calc_Runway])<0.01),"PASS","FAIL")) | AY18: =IF([@App_MoMGrowth]="","",IF(OR(AND([@App_MoMGrowth]="N/A",[@Calc_MoMGrowth]="N/A"),ABS([@App_MoMGrowth]-[@Calc_MoMGrowth])<0.0001),"PASS","FAIL")) | AZ18: =IF([@App_NRR]="","",IF(OR(AND([@App_NRR]="N/A",[@Calc_NRR]="N/A"),ABS([@App_NRR]-[@Calc_NRR])<0.0001),"PASS","FAIL")) | BA18: =IF([@App_CAC]="","",IF(OR(AND([@App_CAC]="N/A",[@Calc_CAC]="N/A"),ABS([@App_CAC]-[@Calc_CAC])<0.01),"PASS","FAIL")) | BB18: =IF([@App_LTV]="","",IF(OR(AND([@App_LTV]="N/A",[@Calc_LTV]="N/A"),ABS([@App_LTV]-[@Calc_LTV])<0.01),"PASS","FAIL")) | BC18: =IF([@App_Payback]="","",IF(OR(AND([@App_Payback]="N/A",[@Calc_Payback]="N/A"),ABS([@App_Payback]-[@Calc_Payback])<0.01),"PASS","FAIL"))
A19: TC18_MOMGROWTH_NEGATIVE | H19: 200000 | I19: 150000 | S19: -25% MoM growth | X19: -0.25 | AL19: =IF([@MRR]="", "", [@MRR]*12) | AM19: =IF(OR([@Revenue]="",[@Revenue]<=0), "", ([@Revenue]-[@COGS]) / [@Revenue]) | AN19: =IF(OR([@Revenue]="",[@OpEx]="",[@COGS]=""), "", MAX(0, [@OpEx]+[@COGS]-[@Revenue])) | AO19: =IF([@Cash]="", "", IF(OR([@Burn]="",[@Burn]=0), IF([@Calc_Burn]="", "", IF([@Calc_Burn]<=0, "Cashflow+", [@Cash]/[@Calc_Burn])), IF([@Burn]<=0, "Cashflow+", [@Cash]/[@Burn]))) | AP19: =IF(OR([@Prev]="",[@Curr]=""), "", IF([@Prev]<1000, "N/A", ([@Curr]-[@Prev]) / [@Prev])) | AQ19: =IF([@StartMRR]="", "", IF([@StartMRR]<1000, "N/A", ([@StartMRR]+[@Expansion]-[@Contraction]-[@Churn]) / [@StartMRR])) | AR19: =IF(OR([@Spend]="",[@NewCustomers]=""), "", IF([@NewCustomers]<=0, "N/A", [@Spend]/[@NewCustomers])) | AS19: =IF(OR([@ARPA]="",[@GM]="",[@ChurnRate]=""), "", IF([@ChurnRate]<=0, "N/A", [@ARPA]*[@GM]/[@ChurnRate])) | AT19: =IF(OR([@ARPA]="",[@GM]=""), "", IF(([@ARPA]*[@GM])<=0, "N/A", 200/([@ARPA]*[@GM]))) | AU19: =IF([@App_ARR]="","",IF(ABS([@App_ARR]-[@Calc_ARR])<0.01,"PASS","FAIL")) | AV19: =IF([@App_GM]="","",IF(ABS([@App_GM]-[@Calc_GM])<0.0001,"PASS","FAIL")) | AW19: =IF([@App_Burn]="","",IF(ABS([@App_Burn]-[@Calc_Burn])<1,"PASS","FAIL")) | AX19: =IF([@App_Runway]="","",IF(OR(AND([@App_Runway]="Cashflow+",[@Calc_Runway]="Cashflow+"),ABS([@App_Runway]-[@Calc_Runway])<0.01),"PASS","FAIL")) | AY19: =IF([@App_MoMGrowth]="","",IF(OR(AND([@App_MoMGrowth]="N/A",[@Calc_MoMGrowth]="N/A"),ABS([@App_MoMGrowth]-[@Calc_MoMGrowth])<0.0001),"PASS","FAIL")) | AZ19: =IF([@App_NRR]="","",IF(OR(AND([@App_NRR]="N/A",[@Calc_NRR]="N/A"),ABS([@App_NRR]-[@Calc_NRR])<0.0001),"PASS","FAIL")) | BA19: =IF([@App_CAC]="","",IF(OR(AND([@App_CAC]="N/A",[@Calc_CAC]="N/A"),ABS([@App_CAC]-[@Calc_CAC])<0.01),"PASS","FAIL")) | BB19: =IF([@App_LTV]="","",IF(OR(AND([@App_LTV]="N/A",[@Calc_LTV]="N/A"),ABS([@App_LTV]-[@Calc_LTV])<0.01),"PASS","FAIL")) | BC19: =IF([@App_Payback]="","",IF(OR(AND([@App_Payback]="N/A",[@Calc_Payback]="N/A"),ABS([@App_Payback]-[@Calc_Payback])<0.01),"PASS","FAIL"))
A20: TC19_NRR_NORMAL | J20: 100000 | K20: 20000 | L20: 5000 | M20: 10000 | S20: NRR=1.05 | Y20: 1.05 | AL20: =IF([@MRR]="", "", [@MRR]*12) | AM20: =IF(OR([@Revenue]="",[@Revenue]<=0), "", ([@Revenue]-[@COGS]) / [@Revenue]) | AN20: =IF(OR([@Revenue]="",[@OpEx]="",[@COGS]=""), "", MAX(0, [@OpEx]+[@COGS]-[@Revenue])) | AO20: =IF([@Cash]="", "", IF(OR([@Burn]="",[@Burn]=0), IF([@Calc_Burn]="", "", IF([@Calc_Burn]<=0, "Cashflow+", [@Cash]/[@Calc_Burn])), IF([@Burn]<=0, "Cashflow+", [@Cash]/[@Burn]))) | AP20: =IF(OR([@Prev]="",[@Curr]=""), "", IF([@Prev]<1000, "N/A", ([@Curr]-[@Prev]) / [@Prev])) | AQ20: =IF([@StartMRR]="", "", IF([@StartMRR]<1000, "N/A", ([@StartMRR]+[@Expansion]-[@Contraction]-[@Churn]) / [@StartMRR])) | AR20: =IF(OR([@Spend]="",[@NewCustomers]=""), "", IF([@NewCustomers]<=0, "N/A", [@Spend]/[@NewCustomers])) | AS20: =IF(OR([@ARPA]="",[@GM]="",[@ChurnRate]=""), "", IF([@ChurnRate]<=0, "N/A", [@ARPA]*[@GM]/[@ChurnRate])) | AT20: =IF(OR([@ARPA]="",[@GM]=""), "", IF(([@ARPA]*[@GM])<=0, "N/A", 200/([@ARPA]*[@GM]))) | AU20: =IF([@App_ARR]="","",IF(ABS([@App_ARR]-[@Calc_ARR])<0.01,"PASS","FAIL")) | AV20: =IF([@App_GM]="","",IF(ABS([@App_GM]-[@Calc_GM])<0.0001,"PASS","FAIL")) | AW20: =IF([@App_Burn]="","",IF(ABS([@App_Burn]-[@Calc_Burn])<1,"PASS","FAIL")) | AX20: =IF([@App_Runway]="","",IF(OR(AND([@App_Runway]="Cashflow+",[@Calc_Runway]="Cashflow+"),ABS([@App_Runway]-[@Calc_Runway])<0.01),"PASS","FAIL")) | AY20: =IF([@App_MoMGrowth]="","",IF(OR(AND([@App_MoMGrowth]="N/A",[@Calc_MoMGrowth]="N/A"),ABS([@App_MoMGrowth]-[@Calc_MoMGrowth])<0.0001),"PASS","FAIL")) | AZ20: =IF([@App_NRR]="","",IF(OR(AND([@App_NRR]="N/A",[@Calc_NRR]="N/A"),ABS([@App_NRR]-[@Calc_NRR])<0.0001),"PASS","FAIL")) | BA20: =IF([@App_CAC]="","",IF(OR(AND([@App_CAC]="N/A",[@Calc_CAC]="N/A"),ABS([@App_CAC]-[@Calc_CAC])<0.01),"PASS","FAIL")) | BB20: =IF([@App_LTV]="","",IF(OR(AND([@App_LTV]="N/A",[@Calc_LTV]="N/A"),ABS([@App_LTV]-[@Calc_LTV])<0.01),"PASS","FAIL")) | BC20: =IF([@App_Payback]="","",IF(OR(AND([@App_Payback]="N/A",[@Calc_Payback]="N/A"),ABS([@App_Payback]-[@Calc_Payback])<0.01),"PASS","FAIL"))
A21: TC20_NRR_DENOM_SMALL | J21: 500 | K21: 200 | L21: 0 | M21: 0 | S21: StartMRR<1000 => N/A | Y21: N/A | AL21: =IF([@MRR]="", "", [@MRR]*12) | AM21: =IF(OR([@Revenue]="",[@Revenue]<=0), "", ([@Revenue]-[@COGS]) / [@Revenue]) | AN21: =IF(OR([@Revenue]="",[@OpEx]="",[@COGS]=""), "", MAX(0, [@OpEx]+[@COGS]-[@Revenue])) | AO21: =IF([@Cash]="", "", IF(OR([@Burn]="",[@Burn]=0), IF([@Calc_Burn]="", "", IF([@Calc_Burn]<=0, "Cashflow+", [@Cash]/[@Calc_Burn])), IF([@Burn]<=0, "Cashflow+", [@Cash]/[@Burn]))) | AP21: =IF(OR([@Prev]="",[@Curr]=""), "", IF([@Prev]<1000, "N/A", ([@Curr]-[@Prev]) / [@Prev])) | AQ21: =IF([@StartMRR]="", "", IF([@StartMRR]<1000, "N/A", ([@StartMRR]+[@Expansion]-[@Contraction]-[@Churn]) / [@StartMRR])) | AR21: =IF(OR([@Spend]="",[@NewCustomers]=""), "", IF([@NewCustomers]<=0, "N/A", [@Spend]/[@NewCustomers])) | AS21: =IF(OR([@ARPA]="",[@GM]="",[@ChurnRate]=""), "", IF([@ChurnRate]<=0, "N/A", [@ARPA]*[@GM]/[@ChurnRate])) | AT21: =IF(OR([@ARPA]="",[@GM]=""), "", IF(([@ARPA]*[@GM])<=0, "N/A", 200/([@ARPA]*[@GM]))) | AU21: =IF([@App_ARR]="","",IF(ABS([@App_ARR]-[@Calc_ARR])<0.01,"PASS","FAIL")) | AV21: =IF([@App_GM]="","",IF(ABS([@App_GM]-[@Calc_GM])<0.0001,"PASS","FAIL")) | AW21: =IF([@App_Burn]="","",IF(ABS([@App_Burn]-[@Calc_Burn])<1,"PASS","FAIL")) | AX21: =IF([@App_Runway]="","",IF(OR(AND([@App_Runway]="Cashflow+",[@Calc_Runway]="Cashflow+"),ABS([@App_Runway]-[@Calc_Runway])<0.01),"PASS","FAIL")) | AY21: =IF([@App_MoMGrowth]="","",IF(OR(AND([@App_MoMGrowth]="N/A",[@Calc_MoMGrowth]="N/A"),ABS([@App_MoMGrowth]-[@Calc_MoMGrowth])<0.0001),"PASS","FAIL")) | AZ21: =IF([@App_NRR]="","",IF(OR(AND([@App_NRR]="N/A",[@Calc_NRR]="N/A"),ABS([@App_NRR]-[@Calc_NRR])<0.0001),"PASS","FAIL")) | BA21: =IF([@App_CAC]="","",IF(OR(AND([@App_CAC]="N/A",[@Calc_CAC]="N/A"),ABS([@App_CAC]-[@Calc_CAC])<0.01),"PASS","FAIL")) | BB21: =IF([@App_LTV]="","",IF(OR(AND([@App_LTV]="N/A",[@Calc_LTV]="N/A"),ABS([@App_LTV]-[@Calc_LTV])<0.01),"PASS","FAIL")) | BC21: =IF([@App_Payback]="","",IF(OR(AND([@App_Payback]="N/A",[@Calc_Payback]="N/A"),ABS([@App_Payback]-[@Calc_Payback])<0.01),"PASS","FAIL"))
A22: TC21_NRR_OUTLIER | J22: 10000 | K22: 50000 | L22: 0 | M22: 0 | S22: NRR=6.0 => OUTLIER warning expected in app | Y22: 6 | AL22: =IF([@MRR]="", "", [@MRR]*12) | AM22: =IF(OR([@Revenue]="",[@Revenue]<=0), "", ([@Revenue]-[@COGS]) / [@Revenue]) | AN22: =IF(OR([@Revenue]="",[@OpEx]="",[@COGS]=""), "", MAX(0, [@OpEx]+[@COGS]-[@Revenue])) | AO22: =IF([@Cash]="", "", IF(OR([@Burn]="",[@Burn]=0), IF([@Calc_Burn]="", "", IF([@Calc_Burn]<=0, "Cashflow+", [@Cash]/[@Calc_Burn])), IF([@Burn]<=0, "Cashflow+", [@Cash]/[@Burn]))) | AP22: =IF(OR([@Prev]="",[@Curr]=""), "", IF([@Prev]<1000, "N/A", ([@Curr]-[@Prev]) / [@Prev])) | AQ22: =IF([@StartMRR]="", "", IF([@StartMRR]<1000, "N/A", ([@StartMRR]+[@Expansion]-[@Contraction]-[@Churn]) / [@StartMRR])) | AR22: =IF(OR([@Spend]="",[@NewCustomers]=""), "", IF([@NewCustomers]<=0, "N/A", [@Spend]/[@NewCustomers])) | AS22: =IF(OR([@ARPA]="",[@GM]="",[@ChurnRate]=""), "", IF([@ChurnRate]<=0, "N/A", [@ARPA]*[@GM]/[@ChurnRate])) | AT22: =IF(OR([@ARPA]="",[@GM]=""), "", IF(([@ARPA]*[@GM])<=0, "N/A", 200/([@ARPA]*[@GM]))) | AU22: =IF([@App_ARR]="","",IF(ABS([@App_ARR]-[@Calc_ARR])<0.01,"PASS","FAIL")) | AV22: =IF([@App_GM]="","",IF(ABS([@App_GM]-[@Calc_GM])<0.0001,"PASS","FAIL")) | AW22: =IF([@App_Burn]="","",IF(ABS([@App_Burn]-[@Calc_Burn])<1,"PASS","FAIL")) | AX22: =IF([@App_Runway]="","",IF(OR(AND([@App_Runway]="Cashflow+",[@Calc_Runway]="Cashflow+"),ABS([@App_Runway]-[@Calc_Runway])<0.01),"PASS","FAIL")) | AY22: =IF([@App_MoMGrowth]="","",IF(OR(AND([@App_MoMGrowth]="N/A",[@Calc_MoMGrowth]="N/A"),ABS([@App_MoMGrowth]-[@Calc_MoMGrowth])<0.0001),"PASS","FAIL")) | AZ22: =IF([@App_NRR]="","",IF(OR(AND([@App_NRR]="N/A",[@Calc_NRR]="N/A"),ABS([@App_NRR]-[@Calc_NRR])<0.0001),"PASS","FAIL")) | BA22: =IF([@App_CAC]="","",IF(OR(AND([@App_CAC]="N/A",[@Calc_CAC]="N/A"),ABS([@App_CAC]-[@Calc_CAC])<0.01),"PASS","FAIL")) | BB22: =IF([@App_LTV]="","",IF(OR(AND([@App_LTV]="N/A",[@Calc_LTV]="N/A"),ABS([@App_LTV]-[@Calc_LTV])<0.01),"PASS","FAIL")) | BC22: =IF([@App_Payback]="","",IF(OR(AND([@App_Payback]="N/A",[@Calc_Payback]="N/A"),ABS([@App_Payback]-[@Calc_Payback])<0.01),"PASS","FAIL"))
A23: TC22_NRR_CONTRACTION | J23: 100000 | K23: 0 | L23: 15000 | M23: 5000 | S23: NRR=0.80 | Y23: 0.8 | AL23: =IF([@MRR]="", "", [@MRR]*12) | AM23: =IF(OR([@Revenue]="",[@Revenue]<=0), "", ([@Revenue]-[@COGS]) / [@Revenue]) | AN23: =IF(OR([@Revenue]="",[@OpEx]="",[@COGS]=""), "", MAX(0, [@OpEx]+[@COGS]-[@Revenue])) | AO23: =IF([@Cash]="", "", IF(OR([@Burn]="",[@Burn]=0), IF([@Calc_Burn]="", "", IF([@Calc_Burn]<=0, "Cashflow+", [@Cash]/[@Calc_Burn])), IF([@Burn]<=0, "Cashflow+", [@Cash]/[@Burn]))) | AP23: =IF(OR([@Prev]="",[@Curr]=""), "", IF([@Prev]<1000, "N/A", ([@Curr]-[@Prev]) / [@Prev])) | AQ23: =IF([@StartMRR]="", "", IF([@StartMRR]<1000, "N/A", ([@StartMRR]+[@Expansion]-[@Contraction]-[@Churn]) / [@StartMRR])) | AR23: =IF(OR([@Spend]="",[@NewCustomers]=""), "", IF([@NewCustomers]<=0, "N/A", [@Spend]/[@NewCustomers])) | AS23: =IF(OR([@ARPA]="",[@GM]="",[@ChurnRate]=""), "", IF([@ChurnRate]<=0, "N/A", [@ARPA]*[@GM]/[@ChurnRate])) | AT23: =IF(OR([@ARPA]="",[@GM]=""), "", IF(([@ARPA]*[@GM])<=0, "N/A", 200/([@ARPA]*[@GM]))) | AU23: =IF([@App_ARR]="","",IF(ABS([@App_ARR]-[@Calc_ARR])<0.01,"PASS","FAIL")) | AV23: =IF([@App_GM]="","",IF(ABS([@App_GM]-[@Calc_GM])<0.0001,"PASS","FAIL")) | AW23: =IF([@App_Burn]="","",IF(ABS([@App_Burn]-[@Calc_Burn])<1,"PASS","FAIL")) | AX23: =IF([@App_Runway]="","",IF(OR(AND([@App_Runway]="Cashflow+",[@Calc_Runway]="Cashflow+"),ABS([@App_Runway]-[@Calc_Runway])<0.01),"PASS","FAIL")) | AY23: =IF([@App_MoMGrowth]="","",IF(OR(AND([@App_MoMGrowth]="N/A",[@Calc_MoMGrowth]="N/A"),ABS([@App_MoMGrowth]-[@Calc_MoMGrowth])<0.0001),"PASS","FAIL")) | AZ23: =IF([@App_NRR]="","",IF(OR(AND([@App_NRR]="N/A",[@Calc_NRR]="N/A"),ABS([@App_NRR]-[@Calc_NRR])<0.0001),"PASS","FAIL")) | BA23: =IF([@App_CAC]="","",IF(OR(AND([@App_CAC]="N/A",[@Calc_CAC]="N/A"),ABS([@App_CAC]-[@Calc_CAC])<0.01),"PASS","FAIL")) | BB23: =IF([@App_LTV]="","",IF(OR(AND([@App_LTV]="N/A",[@Calc_LTV]="N/A"),ABS([@App_LTV]-[@Calc_LTV])<0.01),"PASS","FAIL")) | BC23: =IF([@App_Payback]="","",IF(OR(AND([@App_Payback]="N/A",[@Calc_Payback]="N/A"),ABS([@App_Payback]-[@Calc_Payback])<0.01),"PASS","FAIL"))
A24: TC23_CAC_BASIC | Q24: 200000 | R24: 1000 | S24: CAC=200 | Z24: 200 | AL24: =IF([@MRR]="", "", [@MRR]*12) | AM24: =IF(OR([@Revenue]="",[@Revenue]<=0), "", ([@Revenue]-[@COGS]) / [@Revenue]) | AN24: =IF(OR([@Revenue]="",[@OpEx]="",[@COGS]=""), "", MAX(0, [@OpEx]+[@COGS]-[@Revenue])) | AO24: =IF([@Cash]="", "", IF(OR([@Burn]="",[@Burn]=0), IF([@Calc_Burn]="", "", IF([@Calc_Burn]<=0, "Cashflow+", [@Cash]/[@Calc_Burn])), IF([@Burn]<=0, "Cashflow+", [@Cash]/[@Burn]))) | AP24: =IF(OR([@Prev]="",[@Curr]=""), "", IF([@Prev]<1000, "N/A", ([@Curr]-[@Prev]) / [@Prev])) | AQ24: =IF([@StartMRR]="", "", IF([@StartMRR]<1000, "N/A", ([@StartMRR]+[@Expansion]-[@Contraction]-[@Churn]) / [@StartMRR])) | AR24: =IF(OR([@Spend]="",[@NewCustomers]=""), "", IF([@NewCustomers]<=0, "N/A", [@Spend]/[@NewCustomers])) | AS24: =IF(OR([@ARPA]="",[@GM]="",[@ChurnRate]=""), "", IF([@ChurnRate]<=0, "N/A", [@ARPA]*[@GM]/[@ChurnRate])) | AT24: =IF(OR([@ARPA]="",[@GM]=""), "", IF(([@ARPA]*[@GM])<=0, "N/A", 200/([@ARPA]*[@GM]))) | AU24: =IF([@App_ARR]="","",IF(ABS([@App_ARR]-[@Calc_ARR])<0.01,"PASS","FAIL")) | AV24: =IF([@App_GM]="","",IF(ABS([@App_GM]-[@Calc_GM])<0.0001,"PASS","FAIL")) | AW24: =IF([@App_Burn]="","",IF(ABS([@App_Burn]-[@Calc_Burn])<1,"PASS","FAIL")) | AX24: =IF([@App_Runway]="","",IF(OR(AND([@App_Runway]="Cashflow+",[@Calc_Runway]="Cashflow+"),ABS([@App_Runway]-[@Calc_Runway])<0.01),"PASS","FAIL")) | AY24: =IF([@App_MoMGrowth]="","",IF(OR(AND([@App_MoMGrowth]="N/A",[@Calc_MoMGrowth]="N/A"),ABS([@App_MoMGrowth]-[@Calc_MoMGrowth])<0.0001),"PASS","FAIL")) | AZ24: =IF([@App_NRR]="","",IF(OR(AND([@App_NRR]="N/A",[@Calc_NRR]="N/A"),ABS([@App_NRR]-[@Calc_NRR])<0.0001),"PASS","FAIL")) | BA24: =IF([@App_CAC]="","",IF(OR(AND([@App_CAC]="N/A",[@Calc_CAC]="N/A"),ABS([@App_CAC]-[@Calc_CAC])<0.01),"PASS","FAIL")) | BB24: =IF([@App_LTV]="","",IF(OR(AND([@App_LTV]="N/A",[@Calc_LTV]="N/A"),ABS([@App_LTV]-[@Calc_LTV])<0.01),"PASS","FAIL")) | BC24: =IF([@App_Payback]="","",IF(OR(AND([@App_Payback]="N/A",[@Calc_Payback]="N/A"),ABS([@App_Payback]-[@Calc_Payback])<0.01),"PASS","FAIL"))
A25: TC24_CAC_ZERO_CUSTOMERS | Q25: 200000 | R25: 0 | S25: CAC N/A | Z25: N/A | AL25: =IF([@MRR]="", "", [@MRR]*12) | AM25: =IF(OR([@Revenue]="",[@Revenue]<=0), "", ([@Revenue]-[@COGS]) / [@Revenue]) | AN25: =IF(OR([@Revenue]="",[@OpEx]="",[@COGS]=""), "", MAX(0, [@OpEx]+[@COGS]-[@Revenue])) | AO25: =IF([@Cash]="", "", IF(OR([@Burn]="",[@Burn]=0), IF([@Calc_Burn]="", "", IF([@Calc_Burn]<=0, "Cashflow+", [@Cash]/[@Calc_Burn])), IF([@Burn]<=0, "Cashflow+", [@Cash]/[@Burn]))) | AP25: =IF(OR([@Prev]="",[@Curr]=""), "", IF([@Prev]<1000, "N/A", ([@Curr]-[@Prev]) / [@Prev])) | AQ25: =IF([@StartMRR]="", "", IF([@StartMRR]<1000, "N/A", ([@StartMRR]+[@Expansion]-[@Contraction]-[@Churn]) / [@StartMRR])) | AR25: =IF(OR([@Spend]="",[@NewCustomers]=""), "", IF([@NewCustomers]<=0, "N/A", [@Spend]/[@NewCustomers])) | AS25: =IF(OR([@ARPA]="",[@GM]="",[@ChurnRate]=""), "", IF([@ChurnRate]<=0, "N/A", [@ARPA]*[@GM]/[@ChurnRate])) | AT25: =IF(OR([@ARPA]="",[@GM]=""), "", IF(([@ARPA]*[@GM])<=0, "N/A", 200/([@ARPA]*[@GM]))) | AU25: =IF([@App_ARR]="","",IF(ABS([@App_ARR]-[@Calc_ARR])<0.01,"PASS","FAIL")) | AV25: =IF([@App_GM]="","",IF(ABS([@App_GM]-[@Calc_GM])<0.0001,"PASS","FAIL")) | AW25: =IF([@App_Burn]="","",IF(ABS([@App_Burn]-[@Calc_Burn])<1,"PASS","FAIL")) | AX25: =IF([@App_Runway]="","",IF(OR(AND([@App_Runway]="Cashflow+",[@Calc_Runway]="Cashflow+"),ABS([@App_Runway]-[@Calc_Runway])<0.01),"PASS","FAIL")) | AY25: =IF([@App_MoMGrowth]="","",IF(OR(AND([@App_MoMGrowth]="N/A",[@Calc_MoMGrowth]="N/A"),ABS([@App_MoMGrowth]-[@Calc_MoMGrowth])<0.0001),"PASS","FAIL")) | AZ25: =IF([@App_NRR]="","",IF(OR(AND([@App_NRR]="N/A",[@Calc_NRR]="N/A"),ABS([@App_NRR]-[@Calc_NRR])<0.0001),"PASS","FAIL")) | BA25: =IF([@App_CAC]="","",IF(OR(AND([@App_CAC]="N/A",[@Calc_CAC]="N/A"),ABS([@App_CAC]-[@Calc_CAC])<0.01),"PASS","FAIL")) | BB25: =IF([@App_LTV]="","",IF(OR(AND([@App_LTV]="N/A",[@Calc_LTV]="N/A"),ABS([@App_LTV]-[@Calc_LTV])<0.01),"PASS","FAIL")) | BC25: =IF([@App_Payback]="","",IF(OR(AND([@App_Payback]="N/A",[@Calc_Payback]="N/A"),ABS([@App_Payback]-[@Calc_Payback])<0.01),"PASS","FAIL"))
A26: TC25_LTV_BASIC | N26: 50 | O26: 0.7 | P26: 0.05 | S26: LTV=700 | AA26: 700 | AB26: 5.7142857 | AL26: =IF([@MRR]="", "", [@MRR]*12) | AM26: =IF(OR([@Revenue]="",[@Revenue]<=0), "", ([@Revenue]-[@COGS]) / [@Revenue]) | AN26: =IF(OR([@Revenue]="",[@OpEx]="",[@COGS]=""), "", MAX(0, [@OpEx]+[@COGS]-[@Revenue])) | AO26: =IF([@Cash]="", "", IF(OR([@Burn]="",[@Burn]=0), IF([@Calc_Burn]="", "", IF([@Calc_Burn]<=0, "Cashflow+", [@Cash]/[@Calc_Burn])), IF([@Burn]<=0, "Cashflow+", [@Cash]/[@Burn]))) | AP26: =IF(OR([@Prev]="",[@Curr]=""), "", IF([@Prev]<1000, "N/A", ([@Curr]-[@Prev]) / [@Prev])) | AQ26: =IF([@StartMRR]="", "", IF([@StartMRR]<1000, "N/A", ([@StartMRR]+[@Expansion]-[@Contraction]-[@Churn]) / [@StartMRR])) | AR26: =IF(OR([@Spend]="",[@NewCustomers]=""), "", IF([@NewCustomers]<=0, "N/A", [@Spend]/[@NewCustomers])) | AS26: =IF(OR([@ARPA]="",[@GM]="",[@ChurnRate]=""), "", IF([@ChurnRate]<=0, "N/A", [@ARPA]*[@GM]/[@ChurnRate])) | AT26: =IF(OR([@ARPA]="",[@GM]=""), "", IF(([@ARPA]*[@GM])<=0, "N/A", 200/([@ARPA]*[@GM]))) | AU26: =IF([@App_ARR]="","",IF(ABS([@App_ARR]-[@Calc_ARR])<0.01,"PASS","FAIL")) | AV26: =IF([@App_GM]="","",IF(ABS([@App_GM]-[@Calc_GM])<0.0001,"PASS","FAIL")) | AW26: =IF([@App_Burn]="","",IF(ABS([@App_Burn]-[@Calc_Burn])<1,"PASS","FAIL")) | AX26: =IF([@App_Runway]="","",IF(OR(AND([@App_Runway]="Cashflow+",[@Calc_Runway]="Cashflow+"),ABS([@App_Runway]-[@Calc_Runway])<0.01),"PASS","FAIL")) | AY26: =IF([@App_MoMGrowth]="","",IF(OR(AND([@App_MoMGrowth]="N/A",[@Calc_MoMGrowth]="N/A"),ABS([@App_MoMGrowth]-[@Calc_MoMGrowth])<0.0001),"PASS","FAIL")) | AZ26: =IF([@App_NRR]="","",IF(OR(AND([@App_NRR]="N/A",[@Calc_NRR]="N/A"),ABS([@App_NRR]-[@Calc_NRR])<0.0001),"PASS","FAIL")) | BA26: =IF([@App_CAC]="","",IF(OR(AND([@App_CAC]="N/A",[@Calc_CAC]="N/A"),ABS([@App_CAC]-[@Calc_CAC])<0.01),"PASS","FAIL")) | BB26: =IF([@App_LTV]="","",IF(OR(AND([@App_LTV]="N/A",[@Calc_LTV]="N/A"),ABS([@App_LTV]-[@Calc_LTV])<0.01),"PASS","FAIL")) | BC26: =IF([@App_Payback]="","",IF(OR(AND([@App_Payback]="N/A",[@Calc_Payback]="N/A"),ABS([@App_Payback]-[@Calc_Payback])<0.01),"PASS","FAIL"))
A27: TC26_PAYBACK_BASIC | N27: 50 | O27: 0.7 | S27: Payback uses CAC=200 => 5.714mo | AB27: 5.7142857 | AL27: =IF([@MRR]="", "", [@MRR]*12) | AM27: =IF(OR([@Revenue]="",[@Revenue]<=0), "", ([@Revenue]-[@COGS]) / [@Revenue]) | AN27: =IF(OR([@Revenue]="",[@OpEx]="",[@COGS]=""), "", MAX(0, [@OpEx]+[@COGS]-[@Revenue])) | AO27: =IF([@Cash]="", "", IF(OR([@Burn]="",[@Burn]=0), IF([@Calc_Burn]="", "", IF([@Calc_Burn]<=0, "Cashflow+", [@Cash]/[@Calc_Burn])), IF([@Burn]<=0, "Cashflow+", [@Cash]/[@Burn]))) | AP27: =IF(OR([@Prev]="",[@Curr]=""), "", IF([@Prev]<1000, "N/A", ([@Curr]-[@Prev]) / [@Prev])) | AQ27: =IF([@StartMRR]="", "", IF([@StartMRR]<1000, "N/A", ([@StartMRR]+[@Expansion]-[@Contraction]-[@Churn]) / [@StartMRR])) | AR27: =IF(OR([@Spend]="",[@NewCustomers]=""), "", IF([@NewCustomers]<=0, "N/A", [@Spend]/[@NewCustomers])) | AS27: =IF(OR([@ARPA]="",[@GM]="",[@ChurnRate]=""), "", IF([@ChurnRate]<=0, "N/A", [@ARPA]*[@GM]/[@ChurnRate])) | AT27: =IF(OR([@ARPA]="",[@GM]=""), "", IF(([@ARPA]*[@GM])<=0, "N/A", 200/([@ARPA]*[@GM]))) | AU27: =IF([@App_ARR]="","",IF(ABS([@App_ARR]-[@Calc_ARR])<0.01,"PASS","FAIL")) | AV27: =IF([@App_GM]="","",IF(ABS([@App_GM]-[@Calc_GM])<0.0001,"PASS","FAIL")) | AW27: =IF([@App_Burn]="","",IF(ABS([@App_Burn]-[@Calc_Burn])<1,"PASS","FAIL")) | AX27: =IF([@App_Runway]="","",IF(OR(AND([@App_Runway]="Cashflow+",[@Calc_Runway]="Cashflow+"),ABS([@App_Runway]-[@Calc_Runway])<0.01),"PASS","FAIL")) | AY27: =IF([@App_MoMGrowth]="","",IF(OR(AND([@App_MoMGrowth]="N/A",[@Calc_MoMGrowth]="N/A"),ABS([@App_MoMGrowth]-[@Calc_MoMGrowth])<0.0001),"PASS","FAIL")) | AZ27: =IF([@App_NRR]="","",IF(OR(AND([@App_NRR]="N/A",[@Calc_NRR]="N/A"),ABS([@App_NRR]-[@Calc_NRR])<0.0001),"PASS","FAIL")) | BA27: =IF([@App_CAC]="","",IF(OR(AND([@App_CAC]="N/A",[@Calc_CAC]="N/A"),ABS([@App_CAC]-[@Calc_CAC])<0.01),"PASS","FAIL")) | BB27: =IF([@App_LTV]="","",IF(OR(AND([@App_LTV]="N/A",[@Calc_LTV]="N/A"),ABS([@App_LTV]-[@Calc_LTV])<0.01),"PASS","FAIL")) | BC27: =IF([@App_Payback]="","",IF(OR(AND([@App_Payback]="N/A",[@Calc_Payback]="N/A"),ABS([@App_Payback]-[@Calc_Payback])<0.01),"PASS","FAIL"))
A28: TC27_BASELINE_STATUS_QUO_DELTA | B28: 4500000 | C28: 382000 | D28: 520000 | E28: 520000 | F28: 52000 | G28: 850000 | H28: 520000 | I28: 520000 | J28: 100000 | K28: 0 | L28: 0 | M28: 0 | N28: 60 | O28: 0.8 | P28: 0.04 | Q28: 100000 | R28: 1000 | S28: App scenario delta should be 0 for status quo; paste app baseline & scenario outputs in 'App_*' columns | T28: 6240000 | U28: 0.9 | V28: 382000 | W28: 11.780105 | X28: 0 | Y28: 1 | Z28: 100 | AA28: 1200 | AB28: 4.1666667 | AL28: =IF([@MRR]="", "", [@MRR]*12) | AM28: =IF(OR([@Revenue]="",[@Revenue]<=0), "", ([@Revenue]-[@COGS]) / [@Revenue]) | AN28: =IF(OR([@Revenue]="",[@OpEx]="",[@COGS]=""), "", MAX(0, [@OpEx]+[@COGS]-[@Revenue])) | AO28: =IF([@Cash]="", "", IF(OR([@Burn]="",[@Burn]=0), IF([@Calc_Burn]="", "", IF([@Calc_Burn]<=0, "Cashflow+", [@Cash]/[@Calc_Burn])), IF([@Burn]<=0, "Cashflow+", [@Cash]/[@Burn]))) | AP28: =IF(OR([@Prev]="",[@Curr]=""), "", IF([@Prev]<1000, "N/A", ([@Curr]-[@Prev]) / [@Prev])) | AQ28: =IF([@StartMRR]="", "", IF([@StartMRR]<1000, "N/A", ([@StartMRR]+[@Expansion]-[@Contraction]-[@Churn]) / [@StartMRR])) | AR28: =IF(OR([@Spend]="",[@NewCustomers]=""), "", IF([@NewCustomers]<=0, "N/A", [@Spend]/[@NewCustomers])) | AS28: =IF(OR([@ARPA]="",[@GM]="",[@ChurnRate]=""), "", IF([@ChurnRate]<=0, "N/A", [@ARPA]*[@GM]/[@ChurnRate])) | AT28: =IF(OR([@ARPA]="",[@GM]=""), "", IF(([@ARPA]*[@GM])<=0, "N/A", 200/([@ARPA]*[@GM]))) | AU28: =IF([@App_ARR]="","",IF(ABS([@App_ARR]-[@Calc_ARR])<0.01,"PASS","FAIL")) | AV28: =IF([@App_GM]="","",IF(ABS([@App_GM]-[@Calc_GM])<0.0001,"PASS","FAIL")) | AW28: =IF([@App_Burn]="","",IF(ABS([@App_Burn]-[@Calc_Burn])<1,"PASS","FAIL")) | AX28: =IF([@App_Runway]="","",IF(OR(AND([@App_Runway]="Cashflow+",[@Calc_Runway]="Cashflow+"),ABS([@App_Runway]-[@Calc_Runway])<0.01),"PASS","FAIL")) | AY28: =IF([@App_MoMGrowth]="","",IF(OR(AND([@App_MoMGrowth]="N/A",[@Calc_MoMGrowth]="N/A"),ABS([@App_MoMGrowth]-[@Calc_MoMGrowth])<0.0001),"PASS","FAIL")) | AZ28: =IF([@App_NRR]="","",IF(OR(AND([@App_NRR]="N/A",[@Calc_NRR]="N/A"),ABS([@App_NRR]-[@Calc_NRR])<0.0001),"PASS","FAIL")) | BA28: =IF([@App_CAC]="","",IF(OR(AND([@App_CAC]="N/A",[@Calc_CAC]="N/A"),ABS([@App_CAC]-[@Calc_CAC])<0.01),"PASS","FAIL")) | BB28: =IF([@App_LTV]="","",IF(OR(AND([@App_LTV]="N/A",[@Calc_LTV]="N/A"),ABS([@App_LTV]-[@Calc_LTV])<0.01),"PASS","FAIL")) | BC28: =IF([@App_Payback]="","",IF(OR(AND([@App_Payback]="N/A",[@Calc_Payback]="N/A"),ABS([@App_Payback]-[@Calc_Payback])<0.01),"PASS","FAIL"))
